python .\issue_key_testing.py --directory ABYU
RangeIndex(start=0, stop=16, step=1)
Traceback (most recent call last):
  File "C:\Users\SUsman01\AppData\Local\Packages\PythonSoftwareFoundation.Python.3.12_qbz5n2kfra8p0\LocalCache\local-packages\Python312\site-packages\pandas\core\indexes\base.py", line 3805, in get_loc
    return self._engine.get_loc(casted_key)
           ^^^^^^^^^^^^^^^^^^^^^^^^^^^^^^^^
  File "index.pyx", line 167, in pandas._libs.index.IndexEngine.get_loc
  File "index.pyx", line 196, in pandas._libs.index.IndexEngine.get_loc
  File "pandas\\_libs\\hashtable_class_helper.pxi", line 7081, in pandas._libs.hashtable.PyObjectHashTable.get_item
  File "pandas\\_libs\\hashtable_class_helper.pxi", line 7089, in pandas._libs.hashtable.PyObjectHashTable.get_item
KeyError: 'Issue Key'

The above exception was the direct cause of the following exception:

Traceback (most recent call last):
  File "C:\Users\SUsman01\Downloads\Ready\issue_key_testing.py", line 637, in <module>
    main()
  File "C:\Users\SUsman01\Downloads\Ready\issue_key_testing.py", line 548, in main
    logging.info(f"Skipping parent-child update for issue {row['Issue Key']} as it has already been processed.")
                                                           ~~~^^^^^^^^^^^^^
  File "C:\Users\SUsman01\AppData\Local\Packages\PythonSoftwareFoundation.Python.3.12_qbz5n2kfra8p0\LocalCache\local-packages\Python312\site-packages\pandas\core\series.py", line 1121, in __getitem__
    return self._get_value(key)
           ^^^^^^^^^^^^^^^^^^^^
  File "C:\Users\SUsman01\AppData\Local\Packages\PythonSoftwareFoundation.Python.3.12_qbz5n2kfra8p0\LocalCache\local-packages\Python312\site-packages\pandas\core\series.py", line 1237, in _get_value
    loc = self.index.get_loc(label)
          ^^^^^^^^^^^^^^^^^^^^^^^^^
  File "C:\Users\SUsman01\AppData\Local\Packages\PythonSoftwareFoundation.Python.3.12_qbz5n2kfra8p0\LocalCache\local-packages\Python312\site-packages\pandas\core\indexes\base.py", line 3812, in get_loc
    raise KeyError(key) from err
KeyError: 'Issue Key'
